T12368a: Exception:

This is good!
CallStack (from HasCallStack):
  error, called at T12368a.hs:22:17 in main:Main

Package: ghc-internal
Module: GHC.Internal.Exception
Type: ErrorCall

HasCallStack backtrace:
    collectBacktraces, called at libraries/ghc-internal/src/GHC/Internal/Exception.hs:92:13 in ghc-internal:GHC.Internal.Exception
    toExceptionWithBacktrace, called at libraries/ghc-internal/src/GHC/Internal/Exception.hs:128:3 in ghc-internal:GHC.Internal.Exception



